<mujoco model="valley_fold">
    <include file="scene.xml" />
    <extension>
        <plugin plugin="mujoco.elasticity.solid" />
    </extension>
    <worldbody>
        <body name="v1" pos="0.0 -0.005 0.07500000000000001">
            <inertial pos="0 0 0" mass="0.01" diaginertia="1.66667e-05 1.66667e-05 1.66667e-05" />
            <joint name="v1_j1" pos="0 0 0" axis="0 0 1" type="slide" limited="true"
                range="-0.35 0.2" />
        </body>
        <body name="v2" pos="0.06 0.02 0.10500000000000001">
            <inertial pos="0 0 0" mass="0.01" diaginertia="1.66667e-05 1.66667e-05 1.66667e-05" />
            <joint name="v2_j1" pos="0 0 0" axis="1 0 0" type="slide" />
        </body>
        <body name="v3" pos="0.08 -0.04 0.10500000000000001">
            <inertial pos="0 0 0" mass="0.01" diaginertia="1.66667e-05 1.66667e-05 1.66667e-05" />
            <joint name="v3_j1" pos="0 0 0" axis="1 0 0" type="slide" />
            <joint name="v3_j3" pos="0 0 0" axis="0 0 1" type="slide" limited="true" range="0 0.5" />
        </body>
        <body name="v4" pos="0.06 -0.1 0.10500000000000001">
            <inertial pos="0 0 0" mass="0.01" diaginertia="1.66667e-05 1.66667e-05 1.66667e-05" />
            <joint name="v4_j1" pos="0 0 0" axis="1 0 0" type="slide" />
        </body>
        <body name="v5" pos="0.0 -0.08 0.07500000000000001">
            <inertial pos="0 0 0" mass="0.01" diaginertia="1.66667e-05 1.66667e-05 1.66667e-05" />
            <joint name="v5_j1" pos="0 0 0" axis="0 0 1" type="slide" limited="true"
                range="-0.35 0.2" />
        </body>
        <body name="v6" pos="-0.06 0.02 0.10500000000000001">
            <inertial pos="0 0 0" mass="0.01" diaginertia="1.66667e-05 1.66667e-05 1.66667e-05" />
            <joint name="v6_j1" pos="0 0 0" axis="1 0 0" type="slide" />
        </body>
        <body name="v7" pos="-0.08 -0.04 0.10500000000000001">
            <inertial pos="0 0 0" mass="0.01" diaginertia="1.66667e-05 1.66667e-05 1.66667e-05" />
            <joint name="v7_j1" pos="0 0 0" axis="1 0 0" type="slide" />
        </body>
        <body name="v8" pos="-0.06 -0.1 0.10500000000000001">
            <inertial pos="0 0 0" mass="0.01" diaginertia="1.66667e-05 1.66667e-05 1.66667e-05" />
            <joint name="v8_j1" pos="0 0 0" axis="1 0 0" type="slide" />
        </body>
        <!-- <body name="v9" pos="0.0 -0.28 0.10500000000000001">
            <inertial pos="0 0 0" mass="0.001" diaginertia="1.66667e-05 1.66667e-05 1.66667e-05" />
            <joint name="v9_j1" pos="0 0 0" axis="1 0 0" type="slide" />
            <joint name="v9_j2" pos="0 0 0" axis="0 1 0" type="slide" />
            <joint name="v9_j3" pos="0 0 0" axis="0 0 1" type="slide"/>
        </body> -->
        <!-- 0.0 0.2 0.085 -->
        <body name="v10" pos="0.0 0.212 0.132">
            <inertial pos="0 0 0" mass="0.01" diaginertia="1.66667e-05 1.66667e-05 1.66667e-05" />
            <joint name="v10_j1" pos="0 0 0" axis="1 0 0" type="slide" />
            <joint name="v10_j2" pos="0 0 0" axis="0 1 0" type="slide" />
            <joint name="v10_j3" pos="0 0 0" axis="0 0 1" type="slide" />
        </body>
        <body name="ball" pos="0.0 0.205 0.134">
            <freejoint name="ball" />
            <geom name="ball" type="sphere" size="0.01" rgba="0 1 0 1" mass="0.00005"
                friction="3 0.005 0.0001" />
        </body>
    </worldbody>
    <deformable>
        <flex name="body1" dim="2" body="v1 v2 v4 v5" vertex="0 0 0 0 0 0 0 0 0 0 0 0"
            element="0 1 2 2 3 0" rgba="1 0 0 0.9" />
        <flex name="body2" dim="2" body="v2 v3 v4" vertex="0 0 0 0 0 0 0 0 0" element="0 1 2"
            rgba="0 0 1 0.9" />
        <!-- <flex name="body3" dim="2" body="v4 v9 v5" vertex="0 0 0 0 0 0 0 0 0" element="0 1 2"
            rgba="1 0 0 0.9" /> -->
        <!-- <flex name="body4" dim="2" body="v5 v9 v8" vertex="0 0 0 0 0 0 0 0 0" element="0 1 2"
            rgba="1 0 0 0.9" /> -->
        <flex name="body5" dim="2" body="v6 v7 v8" vertex="0 0 0 0 0 0 0 0 0" element="0 1 2"
            rgba="0 0 1 0.9" />
        <flex name="body6" dim="2" body="v1 v6 v8 v5" vertex="0 0 0 0 0 0 0 0 0 0 0 0"
            element="0 1 2 2 3 0" rgba="1 0 0 0.9" />
        <flex name="body7" dim="2" body="v1 v6 v10" vertex="0 0 0 0 0 0 0 0 0" element="0 1 2"
            rgba="1 0 0 0.9" />
        <flex name="body8" dim="2" body="v1 v10 v2" vertex="0 0 0 0 0 0 0 0 0" element="0 1 2"
            rgba="1 0 0 0.9" />
    </deformable>
    <!-- <tendon>
        <fixed name="split">
            <joint joint="v3_j1" coef="0.5" />
            <joint joint="v7_j1" coef="0.5" />
        </fixed>
    </tendon> -->
    <equality>
        <flex flex="body1" />
        <flex flex="body2" />
        <!-- <flex flex="body3" />
        <flex flex="body4" /> -->
        <flex flex="body5" />
        <flex flex="body6" />
        <flex flex="body7" />
        <flex flex="body8" />
        <joint joint1="v3_j1" joint2="v7_j1" polycoef="0 -1 0 0 0" />
        <!-- <joint joint1="v9_j3" joint2="v10_j3" polycoef="0 1 0 0 0" /> -->
    </equality>

    <actuator>
        <position name="v3_actx" joint="v3_j1" kp="200" dampratio="1" ctrlrange="-0.05 0.3" />
        <!-- <position name="v3_actz" joint="v3_j3" kp="10" dampratio="1" ctrlrange="-0.05 0.3" /> -->
    </actuator>
</mujoco>